Workbook

Sheet Financial Statements
B2: BMW Income Statement (in € million) | C2: 2019 | D2: 2020 | E2: 2021 | F2: 2022 | G2: 2023 | H2: 2024 | I2: 2025 | J2: 2026 | K2: 2027 | L2: 2028
B3: Revenues | C3: 104210 | D3: 98990 | E3: 111239 | F3: 142610 | G3: 155498 | H3: =G3*(1+H43) -> 171731.17 | I3: =H3*(1+I43) -> 186653.7 | J3: =I3*(1+J43) -> 199606.48 | K3: =J3*(1+K43) -> 209965.01 | L3: =K3*(1+L43) -> 217186.7
B4: Cost of sales | C4: -86147 | D4: -85408 | E4: -89253 | F4: -118042 | G4: -125809
B5: Gross profit | C5: =C3+C4 -> 18063 | D5: =D3+D4 -> 13582 | E5: =E3+E4 -> 21986 | F5: =F3+F4 -> 24568 | G5: =G3+G4 -> 29689
B6: Selling and administrative expenses | C6: -9367 | D6: -8795 | E6: -9233 | F6: -10616 | G6: -11025
B7: Other operating income and expenses | C7: -1285 | D7: 43 | E7: 647 | F7: 47 | G7: -182
B8: Profit before financial result | C8: =C5+C6+C7 -> 7411 | D8: =D5+D6+D7 -> 4830 | E8: =E5+E6+E7 -> 13400 | F8: =F5+F6+F7 -> 13999 | G8: =G5+G6+G7 -> 18482
B9: Financial result | C9: -293 | D9: 392 | E9: 2660 | F9: 9510 | G9: -1386
B10: Profit before tax | C10: =C8+C9 -> 7118 | D10: =D8+D9 -> 5222 | E10: =E8+E9 -> 16060 | F10: =F8+F9 -> 23509 | G10: =G8+G9 -> 17096
B11: Income taxes | C11: -2140 | D11: -1365 | E11: -3597 | F11: -4927 | G11: -4931
B12: Net profit | C12: =C10+C11 -> 4978 | D12: =D10+D11 -> 3857 | E12: =E10+E11 -> 12463 | F12: =F10+F11 -> 18582 | G12: =G10+G11 -> 12165
B14: BMW Balance Sheet (in € million) | C14: 2019 | D14: 2020 | E14: 2021 | F14: 2022 | G14: 2023 | H14: 2024 | I14: 2025 | J14: 2026 | K14: 2027 | L14: 2028
B15: Intangible assets | C15: 11729 | D15: 12342 | E15: 12980 | F15: 21776 | G15: 20022
B16: Property, plant and equipment | C16: 23245 | D16: 21850 | E16: 22390 | F16: 32126 | G16: 35266
B17: Leased products | C17: 42609 | D17: 41995 | E17: 44700 | F17: 42820 | G17: 43118
B18: Investments accounted for using the equity method | C18: 3199 | D18: 3585 | E18: 5112 | F18: 420 | G18: 443
B19: Other investments | C19: 703 | D19: 735 | E19: 1241 | F19: 1351 | G19: 1197
B20: Receivables from sales financing | C20: 92437 | D20: 84277 | E20: 87417 | F20: 85708 | G20: 87355
B21: Financial assets | C21: 7325 | D21: 7752 | E21: 7515 | F21: 8237 | G21: 5518
B22: Deferred and current tax | C22: 3403 | D22: 3065 | E22: 3731 | F22: 2854 | G22: 3630
B23: Other assets | C23: 12939 | D23: 10326 | E23: 10243 | F23: 10632 | G23: 9133
B24: Inventories | C24: 15891 | D24: 14896 | E24: 15928 | F24: 20005 | G24: 23719
B25: Trade receivables | C25: 2518 | D25: 2298 | E25: 2261 | F25: 4127 | G25: 4162
B26: Cash and cash equivalents | C26: 12036 | D26: 13537 | E26: 16009 | F26: 16870 | G26: 17327
B27: Total assets | C27: =SUM(C15:C26) -> 228034 | D27: =SUM(D15:D26) -> 216658 | E27: =SUM(E15:E26) -> 229527 | F27: =SUM(F15:F26) -> 246926 | G27: =SUM(G15:G26) -> 250890
B28: Equity | C28: 59907 | D28: 61520 | E28: 75132 | F28: 91288 | G28: 92923
B29: Pension provisions | C29: 3335 | D29: 3693 | E29: 1247 | F29: 339 | G29: 427
B30: Other provisions | C30: 13209 | D30: 13982 | E30: 13954 | F30: 15761 | G30: 17037
B31: Deferred and current tax | C31: 1595 | D31: 1256 | E31: 2379 | F31: 3989 | G31: 4198
B32: Financial liabilities | C32: 116740 | D32: 106376 | E32: 103463 | F32: 94196 | G32: 95010
B33: Trade payables | C33: 10182 | D33: 8644 | E33: 10932 | F33: 14120 | G33: 15547
B34: Other liabilities | C34: 23066 | D34: 21187 | E34: 22420 | F34: 27233 | G34: 25748
B35: Total equity and liabilities | C35: =SUM(C28:C34) -> 228034 | D35: =SUM(D28:D34) -> 216658 | E35: =SUM(E28:E34) -> 229527 | F35: =SUM(F28:F34) -> 246926 | G35: =SUM(G28:G34) -> 250890
B37: CAPEX | C37: -6902 | D37: -6150 | E37: -6619 | F37: -9050 | G37: -10881 | H37: =-H3*H49 -> -11035.329 | I37: =-I3*I49 -> -11994.24 | J37: =-J3*J49 -> -12826.577 | K37: =-K3*K49 -> -13492.209 | L37: =-L3*L49 -> -13956.27
B38: Depreciation and amortisation of tangible and intangible assets | C38: 6017 | D38: 6139 | E38: 6495 | F38: 8566 | G38: 8974 | H38: =-H50*G48 -> 8901.368 | I38: =-I50*H48 -> 9187.5137 | J38: =-J50*I48 -> 9636.59 | K38: =-K50*J48 -> 10083.569 | L38: =-L50*K48 -> 10558.716
B39: Changes in Working Capital | C39: -1117 | D39: -996 | E39: 1355 | F39: -523 | G39: -2715 | H39: =H51*H3 -> -1021.0023 | I39: =I51*I3 -> -1109.722 | J39: =J51*J3 -> -1186.7308 | K39: =K51*K3 -> -1248.3159 | L39: =L51*L3 -> -1291.2514
H41: Average or 2024
B42: Assumptions: | I42: 2025 | J42: 2026 | K42: 2027 | L42: 2028
B43: Growth rate of revenues | C43: =(C3-96855)/96855 -> 0.075938258 | D43: =(D3-C3)/C3 -> -0.050091162 | E43: =(E3-D3)/D3 -> 0.12373977 | F43: =(F3-E3)/E3 -> 0.2820144 | G43: =(G3-F3)/F3 -> 0.090372344 | H43: =AVERAGE(C43:G43) -> 0.10439472 | I43: =$H$43-1.75% -> 0.086894723 | J43: =I43-1.75% -> 0.069394723 | K43: =$J$43-1.75% -> 0.051894723 | L43: =$K$43-1.75% -> 0.034394723
B44: Cost of sales/Revenues | C44: =C4/C3 -> -0.82666731 | D44: =D4/D3 -> -0.86279422 | E44: =E4/E3 -> -0.80235349 | F44: =F4/F3 -> -0.82772597 | G44: =G4/G3 -> -0.8090715 | H44: =AVERAGE(C44,E44,F44,G44) -> -0.81645457 | I44: =$H$44 -> -0.81645457 | J44: =$H$44 -> -0.81645457 | K44: =$H$44 -> -0.81645457 | L44: =$H$44 -> -0.81645457
...

Sheet FCF
B2: Free Cash Flows (in € million) | C2: 2024 | D2: 2025 | E2: 2026 | F2: 2027 | G2: 2028
B3: EBIT(1-Tc) | C3: ='Financial Statements'!H3*'Financial Statements'!H47*(1-'Financial Statements'!H52) -> 13483.105 | D3: ='Financial Statements'!I3*'Financial Statements'!I47*(1-'Financial Statements'!I52) -> 14654.716 | E3: ='Financial Statements'!J3*'Financial Statements'!J47*(1-'Financial Statements'!J52) -> 15811.4 | F3: ='Financial Statements'!K3*'Financial Statements'!K47*(1-'Financial Statements'!K52) -> 16631.928 | G3: ='Financial Statements'!L3*'Financial Statements'!L47*(1-'Financial Statements'!L52) -> 17356.01
B4: Depreciation | C4: ='Financial Statements'!H38 -> 8901.368 | D4: ='Financial Statements'!I38 -> 9187.5137 | E4: ='Financial Statements'!J38 -> 9636.59 | F4: ='Financial Statements'!K38 -> 10083.569 | G4: ='Financial Statements'!L38 -> 10558.716
B5: CAPEX | C5: =-'Financial Statements'!H49*'Financial Statements'!H3 -> -11035.329 | D5: =-'Financial Statements'!I49*'Financial Statements'!I3 -> -11994.24 | E5: =-'Financial Statements'!J49*'Financial Statements'!J3 -> -12826.577 | F5: =-'Financial Statements'!K49*'Financial Statements'!K3 -> -13492.209 | G5: =-'Financial Statements'!L49*'Financial Statements'!L3 -> -13956.27
B6: Increases in NWC | C6: =-'Financial Statements'!H51*'Financial Statements'!H3 -> 1021.0023 | D6: =-'Financial Statements'!I51*'Financial Statements'!I3 -> 1109.722 | E6: =-'Financial Statements'!J51*'Financial Statements'!J3 -> 1186.7308 | F6: =-'Financial Statements'!K51*'Financial Statements'!K3 -> 1248.3159 | G6: =-'Financial Statements'!L51*'Financial Statements'!L3 -> 1291.2514
B7: FCF | C7: =C3+C4+C5+C6 -> 12370.147 | D7: =D3+D4+D5+D6 -> 12957.711 | E7: =E3+E4+E5+E6 -> 13808.144 | F7: =F3+F4+F5+F6 -> 14471.605 | G7: =G3+G4+G5+G6 -> 15249.707

Sheet WACC
B2: WACC Calculation:
B4: risk free rate | C4: 0.02815
B5: spread | C5: 0.0142
B6: Cost of debt | C6: =C4+C5 -> 0.04235
B7: Liabilities/Total Assets 2023 | C7: =SUM('Financial Statements'!G29:G34)/'Financial Statements'!G35 -> 0.62962653
B9: stock Beta | C9: 1.08
B10: Market risk premium | C10: =('DAX40'!D10)-C4 -> 0.23196766
B11: Cost of Equity | C11: =C4+C9*C10 -> 0.27867507
B12: Equity/Total Assets 2023 | C12: ='Financial Statements'!G28/'Financial Statements'!G35 -> 0.37037347
B14: WACC | C14: =C6*C7*(1-'Financial Statements'!H52)+C11*C12 -> 0.12187913
B16: g | C16: 0.01

Sheet DCF
B2: DCF | C2: 2024 | D2: 2025 | E2: 2026 | F2: 2027 | G2: 2028 | H2: TV 2028
B3: FCF | C3: =FCF!C3 -> 13483.105 | D3: =FCF!D3 -> 14654.716 | E3: =FCF!E3 -> 15811.4 | F3: =FCF!F3 -> 16631.928 | G3: =FCF!G3 -> 17356.01 | H3: =(G3*(1+G9))/(G8-G9) -> 156683.1
B4: discount factor | C4: =1/(1+G8) -> 0.89136162 | D4: =1/(1+G8)^2 -> 0.79452554 | E4: =1/(1+G8)^3 -> 0.70820957 | F4: =1/(1+G8)^4 -> 0.63127083 | G4: =1/(1+G8)^5 -> 0.56269059 | H4: =G4 -> 0.56269059
B6: Enterprise Value | C6: =C3*C4+D3*D4+E3*E4+F3*F4+G3*G4+H3*H4 -> 143289.08
B8: Net Financial Debt | C8: ='Financial Statements'!G32-'Financial Statements'!G26 -> 77683 | F8: WACC | G8: =WACC!C14 -> 0.12187913
B9: Provisions | C9: ='Financial Statements'!G29+'Financial Statements'!G30 -> 17464 | F9: g | G9: =WACC!C16 -> 0.01
B11: Equity Value | C11: =C6-C8-C9 -> 48142.075
B13: Shares outstanding | C13: 630000000
B15: Stock price (Fair Value) | C15: =(C11*1000000)/C13 -> 76.415992
B17: Current stock price | C17: 73.22
B18: Current Difference (%) | C18: =1-C17/C15 -> 0.041823603
B19: MARGIN OF SAFETY | C19: 0.3
B20: Acceptable buy price (lower limit) | C20: =(1-C19)*C15 -> 53.491194
B21: Upper limit | C21: =(1+C19)*C15 -> 99.34079

Sheet DAX40
B2: Date | C2: DAX40 Price | D2: Return
B3: 43475 | C3: 12263.83 | D3: =(C3-12339.03)/12339.03 -> -0.0060944823
B4: 43840 | C4: 12730.77 | D4: =(C4-C3)/C3 -> 0.038074566
B5: 44206 | C5: 15156.44 | D5: =(C5-C4)/C4 -> 0.190536
B6: 44834 | C6: 12114.36 | D6: =(C6-C5)/C5 -> -0.20071204
B7: 44967 | C7: 15247.1 | D7: =(C7-C6)/C6 -> 0.25859723
B8: 45301 | C8: 19213.14 | D8: =(C8-C7)/C7 -> 0.26011766
B10: Last | D10: =D8 -> 0.26011766
